<?xml version="1.0"?>
<robot name="test_robot">
 <link name="base_link"/>
 
 <link name="link1">
    <visual>
      <origin xyz="0.175 0 0" rpy="0 0 0" />
      <geometry>
          <box size="0.35 0.01 0.01"/>
      </geometry>
    </visual>
 </link>
 
 
 <link name="link2">
     <visual>
      <origin xyz="0.175 0 0" rpy="0 0 0" />
      <geometry>
          <box size="0.35 0.01 0.01"/>
      </geometry>
    </visual>
 </link>
 <link name="tool">
     <visual>
      <origin xyz="0.175 0 0" rpy="0 0 0" />
      <geometry>
          <box size="0.35 0.01 0.01"/>
      </geometry>
    </visual>
 </link>
 
 <joint name="joint1" type="continuous">
  <parent link="base_link"/>
  <child link="link1"/>
  <origin xyz="0 0 0" rpy="1.57 0 0"/>
  <axis xyz="0 0 1"/>
 </joint>

 <joint name="joint2" type="continuous">
  <parent link="link1"/>
  <child link="link2"/>
  <origin xyz="0.35 0 0" rpy="0 0 0"/>
  <axis xyz="0 0 1"/>
 </joint>
 
 <joint name="joint3" type="continuous">
  <parent link="link2"/>
  <child link="tool"/>
  <origin xyz="0.35 0 0" rpy="0 0 0"/>
  <axis xyz="0 0 1"/>
 </joint> 
 
</robot>

